Workbook

Sheet Pre-Audit Scoping
A1: PRE-AUDIT SCOPING & FACILITY PROFILE
A2: Complete this tab before beginning the audit. Answers determine which items apply to this facility.
A4: SECTION 1 — FACILITY & AUDIT INFORMATION
B5: Facility / Site Name | D5: Test
B6: Facility Address | D6: 100 Test Way
B7: City, State, ZIP | D7: Test, Test 12345
B8: NAICS Code | D8: 12345
B9: Approximate Headcount (total employees) | D9: 78
B10: Audit Date(s) | D10: July 7-9 2026
B11: Lead Auditor | D11: Sara Wallon
B12: Co-Auditor(s) | D12: Gabriel Wallon
B13: Audit Scope | D13: Full OSHA GI Compliance Audit
B14: Attorney of Record | D14: Conn Maciel Carey LLP
B15: Privilege Contact (Attorney) | D15: Nick Scala
B16: Audit conducted under attorney-client privilege? | D16: Yes
B17: State / Jurisdiction (State Plan) | D17: Maryland (MOSH)
A18: SECTION 2 — PROCESS & EQUIPMENT INVENTORY
B19: Question | D19: Yes / No | E19: Audit Impact
B20: Does this facility have permit-required confined spaces (PRCS)? | D20: Yes | E20: All Confined Space items (CS-1 through CS-24) apply
B21: Does this facility have powered industrial trucks (forklifts, pallet jacks)? | D21: Yes | E21: All Forklifts & Materials items (PIT-1 through PIT-11) apply
B22: Does this facility have overhead cranes, gantry cranes, or hoists? | D22: Yes | E22: All Cranes, Hoists & Rigging items (CR-1 through CR-10) apply
B23: Does this facility have welding, cutting, or brazing operations? | D23: Yes | E23: All Welding & Hot Work items (WC-1 through WC-10) apply
B24: Do any employees have occupational exposure to blood or OPIM (first aid)? | D24: Yes | E24: Bloodborne Pathogens items BP-1 through BP-7 apply
B25: Does this facility have automatic sprinkler systems? | D25: Yes | E25: Fire Protection items FP-5 through FP-8 (sprinklers) apply
B26: Does this facility have standpipe and hose systems? | D26: No | E26: Fire Protection item FP-16 (standpipe systems) applies
B27: Does this facility use LP gas / propane? | D27: Yes | E27: Hazardous Materials items HM-9 through HM-11 (LP gas) apply
B28: Does this facility have abrasive blasting operations? | D28: No | E28: Occupational Health item OH-1 (abrasive blasting ventilation) applies
B29: Does this facility have spray finishing / painting operations? | D29: No | E29: Occupational Health item OH-3 (spray finishing ventilation) applies
B30: Does this facility have mechanical power presses? | D30: No | E30: Machine Guarding items MG-11 and MG-12 (power presses) apply
... B34: Does this facility generate or process combustible dust? | D34: Yes | E34: Hazard Communication item HC-10 (combustible dust) applies
A36: SECTION 3 — ATTORNEY-CLIENT PRIVILEGE CERTIFICATION
B37: This audit was conducted at the direction of legal counsel under the protection of attorney-client privilege. All findings, observations, and recommendations contained in this audit instrument are confidential attorney-client communications prepared in anticipation of litigation. This document shall not be disclosed to any party without prior written authorization from legal counsel.
B38: Lead Auditor Signature / Date

Sheet HSE Dashboard
A1: WLS AUDIT COACH OSHA — HSE AUDIT DASHBOARD
A2: National Gypsum Company | WLS Audit Coach OSHA Pilot | Prepared under attorney-client privilege
A3: SITE: | G3: DATE(S): | L3: AUDITOR(S):
A5: OVERALL COMBINED SCORE | H5: FINDING SUMMARY BY RATING
A6: Combined Score | H6: Rating | J6: Count | L6: Total | T6: ='Confined Space'!B8+PPE!B8+'Walking & Working Surfaces'!B8+Recordkeeping!B8+LOTO!B8+'Egress & Emergency Action'!B8+'Fire Protection & Alarms'!B8+'Machine Guarding'!B8+'Electrical Safety'!B8+'Hand & Power Tools'!B8+'Hazard Communication'!B8+'Forklifts & Materials'!B8+'Cranes, Hoists & Rigging'!B8+'Hazardous Materials'!B8+'Occ. Health & Noise'!B8+'Medical & First Aid'!B8+'Welding & Hot Work'!B8+'BBP & Sanitation'!B8+'State Requirements'!B8 -> 98.6
A7: =T8 -> 0.046465598 | H7: Best Practice | J7: =COUNTIF('Confined Space'!E18:E48,"Best Practice")+COUNTIF(PPE!E18:E51,"Best Practice")+COUNTIF('Walking & Working Surfaces'!E18:E48,"Best Practice")+COUNTIF(Recordkeeping!E18:E59,"Best Practice")+COUNTIF(LOTO!E18:E36,"Best Practice")+COUNTIF('Egress & Emergency Action'!E18:E40,"Best Practice")+COUNTIF('Fire Protection & Alarms'!E18:E40,"Best Practice")+COUNTIF('Machine Guarding'!E18:E32,"Best Practice")+COUNTIF('Electrical Safety'!E18:E38,"Best Practice")+COUNTIF('Hand & Power Tools'!E18:E36,"Best Practice")+COUNTIF('Hazard Communication'!E18:E32,"Best Practice")+COUNTIF('Forklifts & Materials'!E18:E33,"Best Practice")+COUNTIF('Cranes, Hoists & Rigging'!E18:E31,"Best Practice")+COUNTIF('Hazardous Materials'!E18:E31,"Best Practice")+COUNTIF('Occ. Health & Noise'!E18:E29,"Best Practice")+COUNTIF('Medical & First Aid'!E18:E27,"Best Practice")+COUNTIF('Welding & Hot Work'!E18:E30,"Best Practice")+COUNTIF('BBP & Sanitation'!E18:E35,"Best Practice")+COUNTIF('State Requirements'!E19:E118,"Best Practice") -> 3 | L7: =IFERROR(J7/(('Confined Space'!C8-COUNTIF('Confined Space'!E18:E48,"Not Applicable"))+(PPE!C8-COUNTIF(PPE!E18:E51,"Not Applicable"))+('Walking & Working Surfaces'!C8-COUNTIF('Walking & Working Surfaces'!E18:E48,"Not Applicable"))+(Recordkeeping!C8-COUNTIF(Recordkeeping!E18:E59,"Not Applicable"))+(LOTO!C8-COUNTIF(LOTO!E18:E36,"Not Applicable"))+('Egress & Emergency Action'!C8-COUNTIF('Egress & Emergency Action'!E18:E40,"Not Applicable"))+('Fire Protection & Alarms'!C8-COUNTIF('Fire Protection & Alarms'!E18:E40,"Not Applicable"))+('Machine Guarding'!C8-COUNTIF('Machine Guarding'!E18:E32,"Not Applicable"))+('Electrical Safety'!C8-COUNTIF('Electrical Safety'!E18:E38,"Not Applicable"))+('Hand & Power Tools'!C8-COUNTIF('Hand & Power Tools'!E18:E36,"Not Applicable"))+('Hazard Communication'!C8-COUNTIF('Hazard Communication'!E18:E32,"Not Applicable"))+('Forklifts & Materials'!C8-COUNTIF('Forklifts & Materials'!E18:E33,"Not Applicable"))+('Cranes, Hoists & Rigging'!C8-COUNTIF('Cranes, Hoists & Rigging'!E18:E31,"Not Applicable"))+('Hazardous Materials'!C8-COUNTIF('Hazardous Materials'!E18:E31,"Not Applicable"))+('Occ. Health & Noise'!C8-COUNTIF('Occ. Health & Noise'!E18:E29,"Not Applicable"))+('Medical & First Aid'!C8-COUNTIF('Medical & First Aid'!E18:E27,"Not Applicable"))+('Welding & Hot Work'!C8-COUNTIF('Welding & Hot Work'!E18:E30,"Not Applicable"))+('BBP & Sanitation'!C8-COUNTIF('BBP & Sanitation'!E18:E35,"Not Applicable"))+('State Requirements'!C8-COUNTIF('State Requirements'!E19:E118,"Not Applicable"))),"") -> 0.0014164306 | T7: ='Confined Space'!C8+PPE!C8+'Walking & Working Surfaces'!C8+Recordkeeping!C8+LOTO!C8+'Egress & Emergency Action'!C8+'Fire Protection & Alarms'!C8+'Machine Guarding'!C8+'Electrical Safety'!C8+'Hand & Power Tools'!C8+'Hazard Communication'!C8+'Forklifts & Materials'!C8+'Cranes, Hoists & Rigging'!C8+'Hazardous Materials'!C8+'Occ. Health & Noise'!C8+'Medical & First Aid'!C8+'Welding & Hot Work'!C8+'BBP & Sanitation'!C8+'State Requirements'!C8 -> 2122
A8: =T6&" / "&T7 -> 98.6 / 2122 | H8: Verified | J8: =COUNTIF('Confined Space'!E18:E48,"Verified")+COUNTIF(PPE!E18:E51,"Verified")+COUNTIF('Walking & Working Surfaces'!E18:E48,"Verified")+COUNTIF(Recordkeeping!E18:E59,"Verified")+COUNTIF(LOTO!E18:E36,"Verified")+COUNTIF('Egress & Emergency Action'!E18:E40,"Verified")+COUNTIF('Fire Protection & Alarms'!E18:E40,"Verified")+COUNTIF('Machine Guarding'!E18:E32,"Verified")+COUNTIF('Electrical Safety'!E18:E38,"Verified")+COUNTIF('Hand & Power Tools'!E18:E36,"Verified")+COUNTIF('Hazard Communication'!E18:E32,"Verified")+COUNTIF('Forklifts & Materials'!E18:E33,"Verified")+COUNTIF('Cranes, Hoists & Rigging'!E18:E31,"Verified")+COUNTIF('Hazardous Materials'!E18:E31,"Verified")+COUNTIF('Occ. Health & Noise'!E18:E29,"Verified")+COUNTIF('Medical & First Aid'!E18:E27,"Verified")+COUNTIF('Welding & Hot Work'!E18:E30,"Verified")+COUNTIF('BBP & Sanitation'!E18:E35,"Verified")+COUNTIF('State Requirements'!E19:E118,"Verified") -> 3 | L8: =IFERROR(J8/(('Confined Space'!C8-COUNTIF('Confined Space'!E18:E48,"Not Applicable"))+(PPE!C8-COUNTIF(PPE!E18:E51,"Not Applicable"))+('Walking & Working Surfaces'!C8-COUNTIF('Walking & Working Surfaces'!E18:E48,"Not Applicable"))+(Recordkeeping!C8-COUNTIF(Recordkeeping!E18:E59,"Not Applicable"))+(LOTO!C8-COUNTIF(LOTO!E18:E36,"Not Applicable"))+('Egress & Emergency Action'!C8-COUNTIF('Egress & Emergency Action'!E18:E40,"Not Applicable"))+('Fire Protection & Alarms'!C8-COUNTIF('Fire Protection & Alarms'!E18:E40,"Not Applicable"))+('Machine Guarding'!C8-COUNTIF('Machine Guarding'!E18:E32,"Not Applicable"))+('Electrical Safety'!C8-COUNTIF('Electrical Safety'!E18:E38,"Not Applicable"))+('Hand & Power Tools'!C8-COUNTIF('Hand & Power Tools'!E18:E36,"Not Applicable"))+('Hazard Communication'!C8-COUNTIF('Hazard Communication'!E18:E32,"Not Applicable"))+('Forklifts & Materials'!C8-COUNTIF('Forklifts & Materials'!E18:E33,"Not Applicable"))+('Cranes, Hoists & Rigging'!C8-COUNTIF('Cranes, Hoists & Rigging'!E18:E31,"Not Applicable"))+('Hazardous Materials'!C8-COUNTIF('Hazardous Materials'!E18:E31,"Not Applicable"))+('Occ. Health & Noise'!C8-COUNTIF('Occ. Health & Noise'!E18:E29,"Not Applicable"))+('Medical & First Aid'!C8-COUNTIF('Medical & First Aid'!E18:E27,"Not Applicable"))+('Welding & Hot Work'!C8-COUNTIF('Welding & Hot Work'!E18:E30,"Not Applicable"))+('BBP & Sanitation'!C8-COUNTIF('BBP & Sanitation'!E18:E35,"Not Applicable"))+('State Requirements'!C8-COUNTIF('State Requirements'!E19:E118,"Not Applicable"))),"") -> 0.0014164306 | T8: =IF(T7>0,T6/T7,"N/A") -> 0.046465598
A9: Rating Tier | H9: Low | J9: =COUNTIF('Confined Space'!E18:E48,"Low")+COUNTIF(PPE!E18:E51,"Low")+COUNTIF('Walking & Working Surfaces'!E18:E48,"Low")+COUNTIF(Recordkeeping!E18:E59,"Low")+COUNTIF(LOTO!E18:E36,"Low")+COUNTIF('Egress & Emergency Action'!E18:E40,"Low")+COUNTIF('Fire Protection & Alarms'!E18:E40,"Low")+COUNTIF('Machine Guarding'!E18:E32,"Low")+COUNTIF('Electrical Safety'!E18:E38,"Low")+COUNTIF('Hand & Power Tools'!E18:E36,"Low")+COUNTIF('Hazard Communication'!E18:E32,"Low")+COUNTIF('Forklifts & Materials'!E18:E33,"Low")+COUNTIF('Cranes, Hoists & Rigging'!E18:E31,"Low")+COUNTIF('Hazardous Materials'!E18:E31,"Low")+COUNTIF('Occ. Health & Noise'!E18:E29,"Low")+COUNTIF('Medical & First Aid'!E18:E27,"Low")+COUNTIF('Welding & Hot Work'!E18:E30,"Low")+COUNTIF('BBP & Sanitation'!E18:E35,"Low")+COUNTIF('State Requirements'!E19:E118,"Low") -> 4 | L9: =IFERROR(J9/(('Confined Space'!C8-COUNTIF('Confined Space'!E18:E48,"Not Applicable"))+(PPE!C8-COUNTIF(PPE!E18:E51,"Not Applicable"))+('Walking & Working Surfaces'!C8-COUNTIF('Walking & Working Surfaces'!E18:E48,"Not Applicable"))+(Recordkeeping!C8-COUNTIF(Recordkeeping!E18:E59,"Not Applicable"))+(LOTO!C8-COUNTIF(LOTO!E18:E36,"Not Applicable"))+('Egress & Emergency Action'!C8-COUNTIF('Egress & Emergency Action'!E18:E40,"Not Applicable"))+('Fire Protection & Alarms'!C8-COUNTIF('Fire Protection & Alarms'!E18:E40,"Not Applicable"))+('Machine Guarding'!C8-COUNTIF('Machine Guarding'!E18:E32,"Not Applicable"))+('Electrical Safety'!C8-COUNTIF('Electrical Safety'!E18:E38,"Not Applicable"))+('Hand & Power Tools'!C8-COUNTIF('Hand & Power Tools'!E18:E36,"Not Applicable"))+('Hazard Communication'!C8-COUNTIF('Hazard Communication'!E18:E32,"Not Applicable"))+('Forklifts & Materials'!C8-COUNTIF('Forklifts & Materials'!E18:E33,"Not Applicable"))+('Cranes, Hoists & Rigging'!C8-COUNTIF('Cranes, Hoists & Rigging'!E18:E31,"Not Applicable"))+('Hazardous Materials'!C8-COUNTIF('Hazardous Materials'!E18:E31,"Not Applicable"))+('Occ. Health & Noise'!C8-COUNTIF('Occ. Health & Noise'!E18:E29,"Not Applicable"))+('Medical & First Aid'!C8-COUNTIF('Medical & First Aid'!E18:E27,"Not Applicable"))+('Welding & Hot Work'!C8-COUNTIF('Welding & Hot Work'!E18:E30,"Not Applicable"))+('BBP & Sanitation'!C8-COUNTIF('BBP & Sanitation'!E18:E35,"Not Applicable"))+('State Requirements'!C8-COUNTIF('State Requirements'!E19:E118,"Not Applicable"))),"") -> 0.0018885741
A10: =IF(T8="N/A","N/A",IF(T8>=0.99,"Excellence Leader",IF(T8>=0.9,"Gold",IF(T8>=0.8,"Silver",IF(T8>=0.51,"Bronze","Developing"))))) -> Developing | H10: Moderate | J10: =COUNTIF('Confined Space'!E18:E48,"Moderate")+COUNTIF(PPE!E18:E51,"Moderate")+COUNTIF('Walking & Working Surfaces'!E18:E48,"Moderate")+COUNTIF(Recordkeeping!E18:E59,"Moderate")+COUNTIF(LOTO!E18:E36,"Moderate")+COUNTIF('Egress & Emergency Action'!E18:E40,"Moderate")+COUNTIF('Fire Protection & Alarms'!E18:E40,"Moderate")+COUNTIF('Machine Guarding'!E18:E32,"Moderate")+COUNTIF('Electrical Safety'!E18:E38,"Moderate")+COUNTIF('Hand & Power Tools'!E18:E36,"Moderate")+COUNTIF('Hazard Communication'!E18:E32,"Moderate")+COUNTIF('Forklifts & Materials'!E18:E33,"Moderate")+COUNTIF('Cranes, Hoists & Rigging'!E18:E31,"Moderate")+COUNTIF('Hazardous Materials'!E18:E31,"Moderate")+COUNTIF('Occ. Health & Noise'!E18:E29,"Moderate")+COUNTIF('Medical & First Aid'!E18:E27,"Moderate")+COUNTIF('Welding & Hot Work'!E18:E30,"Moderate")+COUNTIF('BBP & Sanitation'!E18:E35,"Moderate")+COUNTIF('State Requirements'!E19:E118,"Moderate") -> 3 | L10: =IFERROR(J10/(('Confined Space'!C8-COUNTIF('Confined Space'!E18:E48,"Not Applicable"))+(PPE!C8-COUNTIF(PPE!E18:E51,"Not Applicable"))+('Walking & Working Surfaces'!C8-COUNTIF('Walking & Working Surfaces'!E18:E48,"Not Applicable"))+(Recordkeeping!C8-COUNTIF(Recordkeeping!E18:E59,"Not Applicable"))+(LOTO!C8-COUNTIF(LOTO!E18:E36,"Not Applicable"))+('Egress & Emergency Action'!C8-COUNTIF('Egress & Emergency Action'!E18:E40,"Not Applicable"))+('Fire Protection & Alarms'!C8-COUNTIF('Fire Protection & Alarms'!E18:E40,"Not Applicable"))+('Machine Guarding'!C8-COUNTIF('Machine Guarding'!E18:E32,"Not Applicable"))+('Electrical Safety'!C8-COUNTIF('Electrical Safety'!E18:E38,"Not Applicable"))+('Hand & Power Tools'!C8-COUNTIF('Hand & Power Tools'!E18:E36,"Not Applicable"))+('Hazard Communication'!C8-COUNTIF('Hazard Communication'!E18:E32,"Not Applicable"))+('Forklifts & Materials'!C8-COUNTIF('Forklifts & Materials'!E18:E33,"Not Applicable"))+('Cranes, Hoists & Rigging'!C8-COUNTIF('Cranes, Hoists & Rigging'!E18:E31,"Not Applicable"))+('Hazardous Materials'!C8-COUNTIF('Hazardous Materials'!E18:E31,"Not Applicable"))+('Occ. Health & Noise'!C8-COUNTIF('Occ. Health & Noise'!E18:E29,"Not Applicable"))+('Medical & First Aid'!C8-COUNTIF('Medical & First Aid'!E18:E27,"Not Applicable"))+('Welding & Hot Work'!C8-COUNTIF('Welding & Hot Work'!E18:E30,"Not Applicable"))+('BBP & Sanitation'!C8-COUNTIF('BBP & Sanitation'!E18:E35,"Not Applicable"))+('State Requirements'!C8-COUNTIF('State Requirements'!E19:E118,"Not Applicable"))),"") -> 0.0014164306
H11: High | J11: =COUNTIF('Confined Space'!E18:E48,"High")+COUNTIF(PPE!E18:E51,"High")+COUNTIF('Walking & Working Surfaces'!E18:E48,"High")+COUNTIF(Recordkeeping!E18:E59,"High")+COUNTIF(LOTO!E18:E36,"High")+COUNTIF('Egress & Emergency Action'!E18:E40,"High")+COUNTIF('Fire Protection & Alarms'!E18:E40,"High")+COUNTIF('Machine Guarding'!E18:E32,"High")+COUNTIF('Electrical Safety'!E18:E38,"High")+COUNTIF('Hand & Power Tools'!E18:E36,"High")+COUNTIF('Hazard Communication'!E18:E32,"High")+COUNTIF('Forklifts & Materials'!E18:E33,"High")+COUNTIF('Cranes, Hoists & Rigging'!E18:E31,"High")+COUNTIF('Hazardous Materials'!E18:E31,"High")+COUNTIF('Occ. Health & Noise'!E18:E29,"High")+COUNTIF('Medical & First Aid'!E18:E27,"High")+COUNTIF('Welding & Hot Work'!E18:E30,"High")+COUNTIF('BBP & Sanitation'!E18:E35,"High")+COUNTIF('State Requirements'!E19:E118,"High") -> 3 | L11: =IFERROR(J11/(('Confined Space'!C8-COUNTIF('Confined Space'!E18:E48,"Not Applicable"))+(PPE!C8-COUNTIF(PPE!E18:E51,"Not Applicable"))+('Walking & Working Surfaces'!C8-COUNTIF('Walking & Working Surfaces'!E18:E48,"Not Applicable"))+(Recordkeeping!C8-COUNTIF(Recordkeeping!E18:E59,"Not Applicable"))+(LOTO!C8-COUNTIF(LOTO!E18:E36,"Not Applicable"))+('Egress & Emergency Action'!C8-COUNTIF('Egress & Emergency Action'!E18:E40,"Not Applicable"))+('Fire Protection & Alarms'!C8-COUNTIF('Fire Protection & Alarms'!E18:E40,"Not Applicable"))+('Machine Guarding'!C8-COUNTIF('Machine Guarding'!E18:E32,"Not Applicable"))+('Electrical Safety'!C8-COUNTIF('Electrical Safety'!E18:E38,"Not Applicable"))+('Hand & Power Tools'!C8-COUNTIF('Hand & Power Tools'!E18:E36,"Not Applicable"))+('Hazard Communication'!C8-COUNTIF('Hazard Communication'!E18:E32,"Not Applicable"))+('Forklifts & Materials'!C8-COUNTIF('Forklifts & Materials'!E18:E33,"Not Applicable"))+('Cranes, Hoists & Rigging'!C8-COUNTIF('Cranes, Hoists & Rigging'!E18:E31,"Not Applicable"))+('Hazardous Materials'!C8-COUNTIF('Hazardous Materials'!E18:E31,"Not Applicable"))+('Occ. Health & Noise'!C8-COUNTIF('Occ. Health & Noise'!E18:E29,"Not Applicable"))+('Medical & First Aid'!C8-COUNTIF('Medical & First Aid'!E18:E27,"Not Applicable"))+('Welding & Hot Work'!C8-COUNTIF('Welding & Hot Work'!E18:E30,"Not Applicable"))+('BBP & Sanitation'!C8-COUNTIF('BBP & Sanitation'!E18:E35,"Not Applicable"))+('State Requirements'!C8-COUNTIF('State Requirements'!E19:E118,"Not Applicable"))),"") -> 0.0014164306
H12: Very High | J12: =COUNTIF('Confined Space'!E18:E48,"Very High")+COUNTIF(PPE!E18:E51,"Very High")+COUNTIF('Walking & Working Surfaces'!E18:E48,"Very High")+COUNTIF(Recordkeeping!E18:E59,"Very High")+COUNTIF(LOTO!E18:E36,"Very High")+COUNTIF('Egress & Emergency Action'!E18:E40,"Very High")+COUNTIF('Fire Protection & Alarms'!E18:E40,"Very High")+COUNTIF('Machine Guarding'!E18:E32,"Very High")+COUNTIF('Electrical Safety'!E18:E38,"Very High")+COUNTIF('Hand & Power Tools'!E18:E36,"Very High")+COUNTIF('Hazard Communication'!E18:E32,"Very High")+COUNTIF('Forklifts & Materials'!E18:E33,"Very High")+COUNTIF('Cranes, Hoists & Rigging'!E18:E31,"Very High")+COUNTIF('Hazardous Materials'!E18:E31,"Very High")+COUNTIF('Occ. Health & Noise'!E18:E29,"Very High")+COUNTIF('Medical & First Aid'!E18:E27,"Very High")+COUNTIF('Welding & Hot Work'!E18:E30,"Very High")+COUNTIF('BBP & Sanitation'!E18:E35,"Very High")+COUNTIF('State Requirements'!E19:E118,"Very High") -> 4 | L12: =IFERROR(J12/(('Confined Space'!C8-COUNTIF('Confined Space'!E18:E48,"Not Applicable"))+(PPE!C8-COUNTIF(PPE!E18:E51,"Not Applicable"))+('Walking & Working Surfaces'!C8-COUNTIF('Walking & Working Surfaces'!E18:E48,"Not Applicable"))+(Recordkeeping!C8-COUNTIF(Recordkeeping!E18:E59,"Not Applicable"))+(LOTO!C8-COUNTIF(LOTO!E18:E36,"Not Applicable"))+('Egress & Emergency Action'!C8-COUNTIF('Egress & Emergency Action'!E18:E40,"Not Applicable"))+('Fire Protection & Alarms'!C8-COUNTIF('Fire Protection & Alarms'!E18:E40,"Not Applicable"))+('Machine Guarding'!C8-COUNTIF('Machine Guarding'!E18:E32,"Not Applicable"))+('Electrical Safety'!C8-COUNTIF('Electrical Safety'!E18:E38,"Not Applicable"))+('Hand & Power Tools'!C8-COUNTIF('Hand & Power Tools'!E18:E36,"Not Applicable"))+('Hazard Communication'!C8-COUNTIF('Hazard Communication'!E18:E32,"Not Applicable"))+('Forklifts & Materials'!C8-COUNTIF('Forklifts & Materials'!E18:E33,"Not Applicable"))+('Cranes, Hoists & Rigging'!C8-COUNTIF('Cranes, Hoists & Rigging'!E18:E31,"Not Applicable"))+('Hazardous Materials'!C8-COUNTIF('Hazardous Materials'!E18:E31,"Not Applicable"))+('Occ. Health & Noise'!C8-COUNTIF('Occ. Health & Noise'!E18:E29,"Not Applicable"))+('Medical & First Aid'!C8-COUNTIF('Medical & First Aid'!E18:E27,"Not Applicable"))+('Welding & Hot Work'!C8-COUNTIF('Welding & Hot Work'!E18:E30,"Not Applicable"))+('BBP & Sanitation'!C8-COUNTIF('BBP & Sanitation'!E18:E35,"Not Applicable"))+('State Requirements'!C8-COUNTIF('State Requirements'!E19:E118,"Not Applicable"))),"") -> 0.0018885741
A13: SECTION SCORES
A14: Conf. Space | C14: PPE | E14: Walk/Work | G14: Recordkeeping | I14: LOTO | K14: Egress | M14: Fire Prot. | O14: Mach. Guard | Q14: Electrical
A15: ='Confined Space'!D8 -> 0.61625 | C15: =PPE!D8 -> 0 | E15: ='Walking & Working Surfaces'!D8 -> 0 | G15: =Recordkeeping!D8 -> 0 | I15: =LOTO!D8 -> 0 | K15: ='Egress & Emergency Action'!D8 -> 0 | M15: ='Fire Protection & Alarms'!D8 -> 0 | O15: ='Machine Guarding'!D8 -> 0 | Q15: ='Electrical Safety'!D8 -> 0
A16: ='Confined Space'!B8&" / "&'Confined Space'!C8 -> 98.6 / 160 | C16: =PPE!B8&" / "&PPE!C8 -> 0 / 193 | E16: ='Walking & Working Surfaces'!B8&" / "&'Walking & Working Surfaces'!C8 -> 0 / 145 | G16: =Recordkeeping!B8&" / "&Recordkeeping!C8 -> 0 / 225 | I16: =LOTO!B8&" / "&LOTO!C8 -> 0 / 142 | K16: ='Egress & Emergency Action'!B8&" / "&'Egress & Emergency Action'!C8 -> 0 / 147 | M16: ='Fire Protection & Alarms'!B8&" / "&'Fire Protection & Alarms'!C8 -> 0 / 124 | O16: ='Machine Guarding'!B8&" / "&'Machine Guarding'!C8 -> 0 / 91 | Q16: ='Electrical Safety'!B8&" / "&'Electrical Safety'!C8 -> 0 / 134
A17: =IF('Confined Space'!D8="N/A","N/A",IF('Confined Space'!D8>=0.99,"Excellence Leader",IF('Confined Space'!D8>=0.9,"Gold",IF('Confined Space'!D8>=0.8,"Silver",IF('Confined Space'!D8>=0.51,"Bronze","Developing"))))) -> Bronze | C17: =IF(PPE!D8="N/A","N/A",IF(PPE!D8>=0.99,"Excellence Leader",IF(PPE!D8>=0.9,"Gold",IF(PPE!D8>=0.8,"Silver",IF(PPE!D8>=0.51,"Bronze","Developing"))))) -> Developing | E17: =IF('Walking & Working Surfaces'!D8="N/A","N/A",IF('Walking & Working Surfaces'!D8>=0.99,"Excellence Leader",IF('Walking & Working Surfaces'!D8>=0.9,"Gold",IF('Walking & Working Surfaces'!D8>=0.8,"Silver",IF('Walking & Working Surfaces'!D8>=0.51,"Bronze","Developing"))))) -> Developing | G17: =IF(Recordkeeping!D8="N/A","N/A",IF(Recordkeeping!D8>=0.99,"Excellence Leader",IF(Recordkeeping!D8>=0.9,"Gold",IF(Recordkeeping!D8>=0.8,"Silver",IF(Recordkeeping!D8>=0.51,"Bronze","Developing"))))) -> Developing | I17: =IF(LOTO!D8="N/A","N/A",IF(LOTO!D8>=0.99,"Excellence Leader",IF(LOTO!D8>=0.9,"Gold",IF(LOTO!D8>=0.8,"Silver",IF(LOTO!D8>=0.51,"Bronze","Developing"))))) -> Developing | K17: =IF('Egress & Emergency Action'!D8="N/A","N/A",IF('Egress & Emergency Action'!D8>=0.99,"Excellence Leader",IF('Egress & Emergency Action'!D8>=0.9,"Gold",IF('Egress & Emergency Action'!D8>=0.8,"Silver",IF('Egress & Emergency Action'!D8>=0.51,"Bronze","Developing"))))) -> Developing | M17: =IF('Fire Protection & Alarms'!D8="N/A","N/A",IF('Fire Protection & Alarms'!D8>=0.99,"Excellence Leader",IF('Fire Protection & Alarms'!D8>=0.9,"Gold",IF('Fire Protection & Alarms'!D8>=0.8,"Silver",IF('Fire Protection & Alarms'!D8>=0.51,"Bronze","Developing"))))) -> Developing | O17: =IF('Machine Guarding'!D8="N/A","N/A",IF('Machine Guarding'!D8>=0.99,"Excellence Leader",IF('Machine Guarding'!D8>=0.9,"Gold",IF('Machine Guarding'!D8>=0.8,"Silver",IF('Machine Guarding'!D8>=0.51,"Bronze","Developing"))))) -> Developing | Q17: =IF('Electrical Safety'!D8="N/A","N/A",IF('Electrical Safety'!D8>=0.99,"Excellence Leader",IF('Electrical Safety'!D8>=0.9,"Gold",IF('Electrical Safety'!D8>=0.8,"Silver",IF('Electrical Safety'!D8>=0.51,"Bronze","Developing"))))) -> Developing
A18: 1910.146 | C18: 1910.132-140 | E18: 1910.22-30 | G18: 1903/1904 | I18: 1910.147 | K18: 1910.36-39 | M18: 1910.157-165 | O18: 1910.212-217 | Q18: 1910.303-335
A20: Tools | C20: HazCom | E20: Forklifts | G20: Cranes | I20: Haz. Mat. | K20: Occ. Health | M20: Medical | O20: Welding | Q20: BBP/Sanit.
A21: ='Hand & Power Tools'!D8 -> 0 | C21: ='Hazard Communication'!D8 -> 0 | E21: ='Forklifts & Materials'!D8 -> 0 | G21: ='Cranes, Hoists & Rigging'!D8 -> 0 | I21: ='Hazardous Materials'!D8 -> 0 | K21: ='Occ. Health & Noise'!D8 -> 0 | M21: ='Medical & First Aid'!D8 -> 0 | O21: ='Welding & Hot Work'!D8 -> 0 | Q21: ='BBP & Sanitation'!D8 -> 0
A22: ='Hand & Power Tools'!B8&" / "&'Hand & Power Tools'!C8 -> 0 / 97 | C22: ='Hazard Communication'!B8&" / "&'Hazard Communication'!C8 -> 0 / 84 | E22: ='Forklifts & Materials'!B8&" / "&'Forklifts & Materials'!C8 -> 0 / 88 | G22: ='Cranes, Hoists & Rigging'!B8&" / "&'Cranes, Hoists & Rigging'!C8 -> 0 / 88 | I22: ='Hazardous Materials'!B8&" / "&'Hazardous Materials'!C8 -> 0 / 84 | K22: ='Occ. Health & Noise'!B8&" / "&'Occ. Health & Noise'!C8 -> 0 / 80 | M22: ='Medical & First Aid'!B8&" / "&'Medical & First Aid'!C8 -> 0 / 68 | O22: ='Welding & Hot Work'!B8&" / "&'Welding & Hot Work'!C8 -> 0 / 76 | Q22: ='BBP & Sanitation'!B8&" / "&'BBP & Sanitation'!C8 -> 0 / 96
A23: =IF('Hand & Power Tools'!D8="N/A","N/A",IF('Hand & Power Tools'!D8>=0.99,"Excellence Leader",IF('Hand & Power Tools'!D8>=0.9,"Gold",IF('Hand & Power Tools'!D8>=0.8,"Silver",IF('Hand & Power Tools'!D8>=0.51,"Bronze","Developing"))))) -> Developing | C23: =IF('Hazard Communication'!D8="N/A","N/A",IF('Hazard Communication'!D8>=0.99,"Excellence Leader",IF('Hazard Communication'!D8>=0.9,"Gold",IF('Hazard Communication'!D8>=0.8,"Silver",IF('Hazard Communication'!D8>=0.51,"Bronze","Developing"))))) -> Developing | E23: =IF('Forklifts & Materials'!D8="N/A","N/A",IF('Forklifts & Materials'!D8>=0.99,"Excellence Leader",IF('Forklifts & Materials'!D8>=0.9,"Gold",IF('Forklifts & Materials'!D8>=0.8,"Silver",IF('Forklifts & Materials'!D8>=0.51,"Bronze","Developing"))))) -> Developing | G23: =IF('Cranes, Hoists & Rigging'!D8="N/A","N/A",IF('Cranes, Hoists & Rigging'!D8>=0.99,"Excellence Leader",IF('Cranes, Hoists & Rigging'!D8>=0.9,"Gold",IF('Cranes, Hoists & Rigging'!D8>=0.8,"Silver",IF('Cranes, Hoists & Rigging'!D8>=0.51,"Bronze","Developing"))))) -> Developing | I23: =IF('Hazardous Materials'!D8="N/A","N/A",IF('Hazardous Materials'!D8>=0.99,"Excellence Leader",IF('Hazardous Materials'!D8>=0.9,"Gold",IF('Hazardous Materials'!D8>=0.8,"Silver",IF('Hazardous Materials'!D8>=0.51,"Bronze","Developing"))))) -> Developing | K23: =IF('Occ. Health & Noise'!D8="N/A","N/A",IF('Occ. Health & Noise'!D8>=0.99,"Excellence Leader",IF('Occ. Health & Noise'!D8>=0.9,"Gold",IF('Occ. Health & Noise'!D8>=0.8,"Silver",IF('Occ. Health & Noise'!D8>=0.51,"Bronze","Developing"))))) -> Developing | M23: =IF('Medical & First Aid'!D8="N/A","N/A",IF('Medical & First Aid'!D8>=0.99,"Excellence Leader",IF('Medical & First Aid'!D8>=0.9,"Gold",IF('Medical & First Aid'!D8>=0.8,"Silver",IF('Medical & First Aid'!D8>=0.51,"Bronze","Developing"))))) -> Developing | O23: =IF('Welding & Hot Work'!D8="N/A","N/A",IF('Welding & Hot Work'!D8>=0.99,"Excellence Leader",IF('Welding & Hot Work'!D8>=0.9,"Gold",IF('Welding & Hot Work'!D8>=0.8,"Silver",IF('Welding & Hot Work'!D8>=0.51,"Bronze","Developing"))))) -> Developing | Q23: =IF('BBP & Sanitation'!D8="N/A","N/A",IF('BBP & Sanitation'!D8>=0.99,"Excellence Leader",IF('BBP & Sanitation'!D8>=0.9,"Gold",IF('BBP & Sanitation'!D8>=0.8,"Silver",IF('BBP & Sanitation'!D8>=0.51,"Bronze","Developing"))))) -> Developing
A24: 1910.241-244 | C24: 1910.1200 | E24: 1910.176,178 | G24: 1910.179-184 | I24: 1910.101,106,110 | K24: 1910.94-95 | M24: 1910.151 | O24: 1910.252-255 | Q24: 1910.1030,141
A26: SCORING TIERS
A27: Excellence Leader ≥99% | D27: Gold 90–98.9% | G27: Silver 80–89.9% | J27: Bronze 51–79.9% | M27: Developing <51%
A28: STATE PLAN SUPPLEMENTAL
A29: State Plan
A30: ='State Requirements'!D8 -> N/A
A31: ='State Requirements'!B8&" / "&'State Requirements'!C8 -> 0 / 0
A32: =IF('State Requirements'!D8="N/A","N/A",IF('State Requirements'!D8>=0.99,"Excellence Leader",IF('State Requirements'!D8>=0.9,"Gold",IF('State Requirements'!D8>=0.8,"Silver",IF('State Requirements'!D8>=0.51,"Bronze","Developing"))))) -> N/A
A33: ='Pre-Audit Scoping'!D17 -> Maryland (MOSH)
A34: State-specific items only

Sheet Audit Report
A1: WLS AUDIT COACH OSHA — AUDIT FINDINGS REPORT
A2: Prepared under attorney-client privilege | Confidential — Not for disclosure without legal counsel authorization
A4: AUDIT INFORMATION
A5: Facility / Site | B5: =IF(ISBLANK('Pre-Audit Scoping'!D5),"[Complete Pre-Audit Scoping tab]",TRIM('Pre-Audit Scoping'!D5)) -> Test
A6: Audit Date(s) | B6: ='Pre-Audit Scoping'!D10 -> July 7-9 2026
A7: Lead Auditor | B7: ='Pre-Audit Scoping'!D11 -> Sara Wallon
A8: Attorney of Record | B8: ='Pre-Audit Scoping'!D14 -> Conn Maciel Carey LLP
A9: Audit Scope | B9: ='Pre-Audit Scoping'!D13 -> Full OSHA GI Compliance Audit
A11: EXECUTIVE SUMMARY
A12: OVERALL SCORE | B12: TIER RATING | C12: SECTIONS AUDITED | D12: TOTAL ITEMS | E12: ITEMS RATED | F12: HIGH / VERY HIGH | G12: SIF-POTENTIAL
A13: =IFERROR(('Confined Space'!B8+PPE!B8+'Walking & Working Surfaces'!B8+Recordkeeping!B8+LOTO!B8+'Egress & Emergency Action'!B8+'Fire Protection & Alarms'!B8+'Machine Guarding'!B8+'Electrical Safety'!B8+'Hand & Power Tools'!B8+'Hazard Communication'!B8+'Forklifts & Materials'!B8+'Cranes, Hoists & Rigging'!B8+'Hazardous Materials'!B8+'Occ. Health & Noise'!B8+'Medical & First Aid'!B8+'Welding & Hot Work'!B8+'BBP & Sanitation'!B8)/('Confined Space'!C8+PPE!C8+'Walking & Working Surfaces'!C8+Recordkeeping!C8+LOTO!C8+'Egress & Emergency Action'!C8+'Fire Protection & Alarms'!C8+'Machine Guarding'!C8+'Electrical Safety'!C8+'Hand & Power Tools'!C8+'Hazard Communication'!C8+'Forklifts & Materials'!C8+'Cranes, Hoists & Rigging'!C8+'Hazardous Materials'!C8+'Occ. Health & Noise'!C8+'Medical & First Aid'!C8+'Welding & Hot Work'!C8+'BBP & Sanitation'!C8),0) -> 0.046465598 | B13: =IF((IFERROR(('Confined Space'!B8+PPE!B8+'Walking & Working Surfaces'!B8+Recordkeeping!B8+LOTO!B8+'Egress & Emergency Action'!B8+'Fire Protection & Alarms'!B8+'Machine Guarding'!B8+'Electrical Safety'!B8+'Hand & Power Tools'!B8+'Hazard Communication'!B8+'Forklifts & Materials'!B8+'Cranes, Hoists & Rigging'!B8+'Hazardous Materials'!B8+'Occ. Health & Noise'!B8+'Medical & First Aid'!B8+'Welding & Hot Work'!B8+'BBP & Sanitation'!B8)/('Confined Space'!C8+PPE!C8+'Walking & Working Surfaces'!C8+Recordkeeping!C8+LOTO!C8+'Egress & Emergency Action'!C8+'Fire Protection & Alarms'!C8+'Machine Guarding'!C8+'Electrical Safety'!C8+'Hand & Power Tools'!C8+'Hazard Communication'!C8+'Forklifts & Materials'!C8+'Cranes, Hoists & Rigging'!C8+'Hazardous Materials'!C8+'Occ. Health & Noise'!C8+'Medical & First Aid'!C8+'Welding & Hot Work'!C8+'BBP & Sanitation'!C8),0))>=0.99,"Excellence Leader",IF((IFERROR(('Confined Space'!B8+PPE!B8+'Walking & Working Surfaces'!B8+Recordkeeping!B8+LOTO!B8+'Egress & Emergency Action'!B8+'Fire Protection & Alarms'!B8+'Machine Guarding'!B8+'Electrical Safety'!B8+'Hand & Power Tools'!B8+'Hazard Communication'!B8+'Forklifts & Materials'!B8+'Cranes, Hoists & Rigging'!B8+'Hazardous Materials'!B8+'Occ. Health & Noise'!B8+'Medical & First Aid'!B8+'Welding & Hot Work'!B8+'BBP & Sanitation'!B8)/('Confined Space'!C8+PPE!C8+'Walking & Working Surfaces'!C8+Recordkeeping!C8+LOTO!C8+'Egress & Emergency Action'!C8+'Fire Protection & Alarms'!C8+'Machine Guarding'!C8+'Electrical Safety'!C8+'Hand & Power Tools'!C8+'Hazard Communication'!C8+'Forklifts & Materials'!C8+'Cranes, Hoists & Rigging'!C8+'Hazardous Materials'!C8+'Occ. Health & Noise'!C8+'Medical & First Aid'!C8+'Welding & Hot Work'!C8+'BBP & Sanitation'!C8),0))>=0.9,"Gold",IF((IFERROR(('Confined Space'!B8+PPE!B8+'Walking & Working Surfaces'!B8+Recordkeeping!B8+LOTO!B8+'Egress & Emergency Action'!B8+'Fire Protection & Alarms'!B8+'Machine Guarding'!B8+'Electrical Safety'!B8+'Hand & Power Tools'!B8+'Hazard Communication'!B8+'Forklifts & Materials'!B8+'Cranes, Hoists & Rigging'!B8+'Hazardous Materials'!B8+'Occ. Health & Noise'!B8+'Medical & First Aid'!B8+'Welding & Hot Work'!B8+'BBP & Sanitation'!B8)/('Confined Space'!C8+PPE!C8+'Walking & Working Surfaces'!C8+Recordkeeping!C8+LOTO!C8+'Egress & Emergency Action'!C8+'Fire Protection & Alarms'!C8+'Machine Guarding'!C8+'Electrical Safety'!C8+'Hand & Power Tools'!C8+'Hazard Communication'!C8+'Forklifts & Materials'!C8+'Cranes, Hoists & Rigging'!C8+'Hazardous Materials'!C8+'Occ. Health & Noise'!C8+'Medical & First Aid'!C8+'Welding & Hot Work'!C8+'BBP & Sanitation'!C8),0))>=0.8,"Silver",IF((IFERROR(('Confined Space'!B8+PPE!B8+'Walking & Working Surfaces'!B8+Recordkeeping!B8+LOTO!B8+'Egress & Emergency Action'!B8+'Fire Protection & Alarms'!B8+'Machine Guarding'!B8+'Electrical Safety'!B8+'Hand & Power Tools'!B8+'Hazard Communication'!B8+'Forklifts & Materials'!B8+'Cranes, Hoists & Rigging'!B8+'Hazardous Materials'!B8+'Occ. Health & Noise'!B8+'Medical & First Aid'!B8+'Welding & Hot Work'!B8+'BBP & Sanitation'!B8)/('Confined Space'!C8+PPE!C8+'Walking & Working Surfaces'!C8+Recordkeeping!C8+LOTO!C8+'Egress & Emergency Action'!C8+'Fire Protection & Alarms'!C8+'Machine Guarding'!C8+'Electrical Safety'!C8+'Hand & Power Tools'!C8+'Hazard Communication'!C8+'Forklifts & Materials'!C8+'Cranes, Hoists & Rigging'!C8+'Hazardous Materials'!C8+'Occ. Health & Noise'!C8+'Medical & First Aid'!C8+'Welding & Hot Work'!C8+'BBP & Sanitation'!C8),0))>=0.51,"Bronze","Developing")))) -> Developing | C13: 18 | D13: =COUNTA(DataPool!E2:E288)-COUNTIF(DataPool!E2:E288,"Select rating") -> 24 | E13: =COUNTA(DataPool!E2:E288)-COUNTIF(DataPool!E2:E288,"Select rating")-COUNTIF(DataPool!E2:E288,"Not Applicable") -> 20 | F13: =COUNTIF(DataPool!E2:E288,"High")+COUNTIF(DataPool!E2:E288,"Very High") -> 7 | G13: =SUMPRODUCT((DataPool!E2:E288="High")+(DataPool!E2:E288="Very High")>0) -> 0
A14: =COUNTIF(DataPool!E2:E288,"Best Practice")&" Best Practice" -> 3 Best Practice | B14: =COUNTIF(DataPool!E2:E288,"Verified")&" Verified" -> 3 Verified | C14: =COUNTIF(DataPool!E2:E288,"Low")&" Low" -> 4 Low | D14: =COUNTIF(DataPool!E2:E288,"Moderate")&" Moderate" -> 3 Moderate | E14: =COUNTIF(DataPool!E2:E288,"High")&" High" -> 3 High | F14: =COUNTIF(DataPool!E2:E288,"Very High")&" Very High" -> 4 Very High | G14: =COUNTIF(DataPool!E2:E288,"Not Applicable")&" Not Applicable" -> 4 Not Applicable
A16: SECTION SCORES
A17: Section | B17: Score | C17: Max | D17: % Score | E17: Tier | F17: Findings | G17: SIF Risk
A18: Confined Space | B18: ='Confined Space'!B8 -> 98.6 | C18: ='Confined Space'!C8 -> 160 | D18: ='Confined Space'!D8 -> 0.61625 | E18: =IF('Confined Space'!D8="N/A","N/A",IF('Confined Space'!D8>=0.99,"Excellence Leader",IF('Confined Space'!D8>=0.9,"Gold",IF('Confined Space'!D8>=0.8,"Silver",IF('Confined Space'!D8>=0.51,"Bronze","Developing"))))) -> Bronze | F18: =COUNTIF('Confined Space'!E19:E48,"Low")+COUNTIF('Confined Space'!E19:E48,"Moderate")+COUNTIF('Confined Space'!E19:E48,"High")+COUNTIF('Confined Space'!E19:E48,"Very High") -> 14
A19: PPE | B19: =PPE!B8 -> 0 | C19: =PPE!C8 -> 193 | D19: =PPE!D8 -> 0 | E19: =IF(PPE!D8="N/A","N/A",IF(PPE!D8>=0.99,"Excellence Leader",IF(PPE!D8>=0.9,"Gold",IF(PPE!D8>=0.8,"Silver",IF(PPE!D8>=0.51,"Bronze","Developing"))))) -> Developing | F19: =COUNTIF(PPE!E19:E51,"Low")+COUNTIF(PPE!E19:E51,"Moderate")+COUNTIF(PPE!E19:E51,"High")+COUNTIF(PPE!E19:E51,"Very High") -> 0
A20: Walk/Work Surfaces | B20: ='Walking & Working Surfaces'!B8 -> 0 | C20: ='Walking & Working Surfaces'!C8 -> 145 | D20: ='Walking & Working Surfaces'!D8 -> 0 | E20: =IF('Walking & Working Surfaces'!D8="N/A","N/A",IF('Walking & Working Surfaces'!D8>=0.99,"Excellence Leader",IF('Walking & Working Surfaces'!D8>=0.9,"Gold",IF('Walking & Working Surfaces'!D8>=0.8,"Silver",IF('Walking & Working Surfaces'!D8>=0.51,"Bronze","Developing"))))) -> Developing | F20: =COUNTIF('Walking & Working Surfaces'!E19:E48,"Low")+COUNTIF('Walking & Working Surfaces'!E19:E48,"Moderate")+COUNTIF('Walking & Working Surfaces'!E19:E48,"High")+COUNTIF('Walking & Working Surfaces'!E19:E48,"Very High") -> 0
A21: Recordkeeping | B21: =Recordkeeping!B8 -> 0 | C21: =Recordkeeping!C8 -> 225 | D21: =Recordkeeping!D8 -> 0 | E21: =IF(Recordkeeping!D8="N/A","N/A",IF(Recordkeeping!D8>=0.99,"Excellence Leader",IF(Recordkeeping!D8>=0.9,"Gold",IF(Recordkeeping!D8>=0.8,"Silver",IF(Recordkeeping!D8>=0.51,"Bronze","Developing"))))) -> Developing | F21: =COUNTIF(Recordkeeping!E19:E59,"Low")+COUNTIF(Recordkeeping!E19:E59,"Moderate")+COUNTIF(Recordkeeping!E19:E59,"High")+COUNTIF(Recordkeeping!E19:E59,"Very High") -> 0
A22: LOTO | B22: =LOTO!B8 -> 0 | C22: =LOTO!C8 -> 142 | D22: =LOTO!D8 -> 0 | E22: =IF(LOTO!D8="N/A","N/A",IF(LOTO!D8>=0.99,"Excellence Leader",IF(LOTO!D8>=0.9,"Gold",IF(LOTO!D8>=0.8,"Silver",IF(LOTO!D8>=0.51,"Bronze","Developing"))))) -> Developing | F22: =COUNTIF(LOTO!E19:E36,"Low")+COUNTIF(LOTO!E19:E36,"Moderate")+COUNTIF(LOTO!E19:E36,"High")+COUNTIF(LOTO!E19:E36,"Very High") -> 0
A23: Egress & Emergency | B23: ='Egress & Emergency Action'!B8 -> 0 | C23: ='Egress & Emergency Action'!C8 -> 147 | D23: ='Egress & Emergency Action'!D8 -> 0 | E23: =IF('Egress & Emergency Action'!D8="N/A","N/A",IF('Egress & Emergency Action'!D8>=0.99,"Excellence Leader",IF('Egress & Emergency Action'!D8>=0.9,"Gold",IF('Egress & Emergency Action'!D8>=0.8,"Silver",IF('Egress & Emergency Action'!D8>=0.51,"Bronze","Developing"))))) -> Developing | F23: =COUNTIF('Egress & Emergency Action'!E19:E40,"Low")+COUNTIF('Egress & Emergency Action'!E19:E40,"Moderate")+COUNTIF('Egress & Emergency Action'!E19:E40,"High")+COUNTIF('Egress & Emergency Action'!E19:E40,"Very High") -> 0
A24: Fire Protection | B24: ='Fire Protection & Alarms'!B8 -> 0 | C24: ='Fire Protection & Alarms'!C8 -> 124 | D24: ='Fire Protection & Alarms'!D8 -> 0 | E24: =IF('Fire Protection & Alarms'!D8="N/A","N/A",IF('Fire Protection & Alarms'!D8>=0.99,"Excellence Leader",IF('Fire Protection & Alarms'!D8>=0.9,"Gold",IF('Fire Protection & Alarms'!D8>=0.8,"Silver",IF('Fire Protection & Alarms'!D8>=0.51,"Bronze","Developing"))))) -> Developing | F24: =COUNTIF('Fire Protection & Alarms'!E19:E40,"Low")+COUNTIF('Fire Protection & Alarms'!E19:E40,"Moderate")+COUNTIF('Fire Protection & Alarms'!E19:E40,"High")+COUNTIF('Fire Protection & Alarms'!E19:E40,"Very High") -> 0
A25: Machine Guarding | B25: ='Machine Guarding'!B8 -> 0 | C25: ='Machine Guarding'!C8 -> 91 | D25: ='Machine Guarding'!D8 -> 0 | E25: =IF('Machine Guarding'!D8="N/A","N/A",IF('Machine Guarding'!D8>=0.99,"Excellence Leader",IF('Machine Guarding'!D8>=0.9,"Gold",IF('Machine Guarding'!D8>=0.8,"Silver",IF('Machine Guarding'!D8>=0.51,"Bronze","Developing"))))) -> Developing | F25: =COUNTIF('Machine Guarding'!E19:E32,"Low")+COUNTIF('Machine Guarding'!E19:E32,"Moderate")+COUNTIF('Machine Guarding'!E19:E32,"High")+COUNTIF('Machine Guarding'!E19:E32,"Very High") -> 0
A26: Electrical Safety | B26: ='Electrical Safety'!B8 -> 0 | C26: ='Electrical Safety'!C8 -> 134 | D26: ='Electrical Safety'!D8 -> 0 | E26: =IF('Electrical Safety'!D8="N/A","N/A",IF('Electrical Safety'!D8>=0.99,"Excellence Leader",IF('Electrical Safety'!D8>=0.9,"Gold",IF('Electrical Safety'!D8>=0.8,"Silver",IF('Electrical Safety'!D8>=0.51,"Bronze","Developing"))))) -> Developing | F26: =COUNTIF('Electrical Safety'!E19:E38,"Low")+COUNTIF('Electrical Safety'!E19:E38,"Moderate")+COUNTIF('Electrical Safety'!E19:E38,"High")+COUNTIF('Electrical Safety'!E19:E38,"Very High") -> 0
A27: Hand & Power Tools | B27: ='Hand & Power Tools'!B8 -> 0 | C27: ='Hand & Power Tools'!C8 -> 97 | D27: ='Hand & Power Tools'!D8 -> 0 | E27: =IF('Hand & Power Tools'!D8="N/A","N/A",IF('Hand & Power Tools'!D8>=0.99,"Excellence Leader",IF('Hand & Power Tools'!D8>=0.9,"Gold",IF('Hand & Power Tools'!D8>=0.8,"Silver",IF('Hand & Power Tools'!D8>=0.51,"Bronze","Developing"))))) -> Developing | F27: =COUNTIF('Hand & Power Tools'!E19:E36,"Low")+COUNTIF('Hand & Power Tools'!E19:E36,"Moderate")+COUNTIF('Hand & Power Tools'!E19:E36,"High")+COUNTIF('Hand & Power Tools'!E19:E36,"Very High") -> 0
A28: Hazard Communication | B28: ='Hazard Communication'!B8 -> 0 | C28: ='Hazard Communication'!C8 -> 84 | D28: ='Hazard Communication'!D8 -> 0 | E28: =IF('Hazard Communication'!D8="N/A","N/A",IF('Hazard Communication'!D8>=0.99,"Excellence Leader",IF('Hazard Communication'!D8>=0.9,"Gold",IF('Hazard Communication'!D8>=0.8,"Silver",IF('Hazard Communication'!D8>=0.51,"Bronze","Developing"))))) -> Developing | F28: =COUNTIF('Hazard Communication'!E19:E32,"Low")+COUNTIF('Hazard Communication'!E19:E32,"Moderate")+COUNTIF('Hazard Communication'!E19:E32,"High")+COUNTIF('Hazard Communication'!E19:E32,"Very High") -> 0
A29: Forklifts | B29: ='Forklifts & Materials'!B8 -> 0 | C29: ='Forklifts & Materials'!C8 -> 88 | D29: ='Forklifts & Materials'!D8 -> 0 | E29: =IF('Forklifts & Materials'!D8="N/A","N/A",IF('Forklifts & Materials'!D8>=0.99,"Excellence Leader",IF('Forklifts & Materials'!D8>=0.9,"Gold",IF('Forklifts & Materials'!D8>=0.8,"Silver",IF('Forklifts & Materials'!D8>=0.51,"Bronze","Developing"))))) -> Developing | F29: =COUNTIF('Forklifts & Materials'!E19:E33,"Low")+COUNTIF('Forklifts & Materials'!E19:E33,"Moderate")+COUNTIF('Forklifts & Materials'!E19:E33,"High")+COUNTIF('Forklifts & Materials'!E19:E33,"Very High") -> 0
A30: Cranes & Rigging | B30: ='Cranes, Hoists & Rigging'!B8 -> 0 | C30: ='Cranes, Hoists & Rigging'!C8 -> 88 | D30: ='Cranes, Hoists & Rigging'!D8 -> 0 | E30: =IF('Cranes, Hoists & Rigging'!D8="N/A","N/A",IF('Cranes, Hoists & Rigging'!D8>=0.99,"Excellence Leader",IF('Cranes, Hoists & Rigging'!D8>=0.9,"Gold",IF('Cranes, Hoists & Rigging'!D8>=0.8,"Silver",IF('Cranes, Hoists & Rigging'!D8>=0.51,"Bronze","Developing"))))) -> Developing | F30: =COUNTIF('Cranes, Hoists & Rigging'!E19:E31,"Low")+COUNTIF('Cranes, Hoists & Rigging'!E19:E31,"Moderate")+COUNTIF('Cranes, Hoists & Rigging'!E19:E31,"High")+COUNTIF('Cranes, Hoists & Rigging'!E19:E31,"Very High") -> 0
A31: Hazardous Materials | B31: ='Hazardous Materials'!B8 -> 0 | C31: ='Hazardous Materials'!C8 -> 84 | D31: ='Hazardous Materials'!D8 -> 0 | E31: =IF('Hazardous Materials'!D8="N/A","N/A",IF('Hazardous Materials'!D8>=0.99,"Excellence Leader",IF('Hazardous Materials'!D8>=0.9,"Gold",IF('Hazardous Materials'!D8>=0.8,"Silver",IF('Hazardous Materials'!D8>=0.51,"Bronze","Developing"))))) -> Developing | F31: =COUNTIF('Hazardous Materials'!E19:E31,"Low")+COUNTIF('Hazardous Materials'!E19:E31,"Moderate")+COUNTIF('Hazardous Materials'!E19:E31,"High")+COUNTIF('Hazardous Materials'!E19:E31,"Very High") -> 0
A32: Occ. Health & Noise | B32: ='Occ. Health & Noise'!B8 -> 0 | C32: ='Occ. Health & Noise'!C8 -> 80 | D32: ='Occ. Health & Noise'!D8 -> 0 | E32: =IF('Occ. Health & Noise'!D8="N/A","N/A",IF('Occ. Health & Noise'!D8>=0.99,"Excellence Leader",IF('Occ. Health & Noise'!D8>=0.9,"Gold",IF('Occ. Health & Noise'!D8>=0.8,"Silver",IF('Occ. Health & Noise'!D8>=0.51,"Bronze","Developing"))))) -> Developing | F32: =COUNTIF('Occ. Health & Noise'!E19:E29,"Low")+COUNTIF('Occ. Health & Noise'!E19:E29,"Moderate")+COUNTIF('Occ. Health & Noise'!E19:E29,"High")+COUNTIF('Occ. Health & Noise'!E19:E29,"Very High") -> 0
A33: Medical & First Aid | B33: ='Medical & First Aid'!B8 -> 0 | C33: ='Medical & First Aid'!C8 -> 68 | D33: ='Medical & First Aid'!D8 -> 0 | E33: =IF('Medical & First Aid'!D8="N/A","N/A",IF('Medical & First Aid'!D8>=0.99,"Excellence Leader",IF('Medical & First Aid'!D8>=0.9,"Gold",IF('Medical & First Aid'!D8>=0.8,"Silver",IF('Medical & First Aid'!D8>=0.51,"Bronze","Developing"))))) -> Developing | F33: =COUNTIF('Medical & First Aid'!E19:E27,"Low")+COUNTIF('Medical & First Aid'!E19:E27,"Moderate")+COUNTIF('Medical & First Aid'!E19:E27,"High")+COUNTIF('Medical & First Aid'!E19:E27,"Very High") -> 0
A34: Welding & Hot Work | B34: ='Welding & Hot Work'!B8 -> 0 | C34: ='Welding & Hot Work'!C8 -> 76 | D34: ='Welding & Hot Work'!D8 -> 0 | E34: =IF('Welding & Hot Work'!D8="N/A","N/A",IF('Welding & Hot Work'!D8>=0.99,"Excellence Leader",IF('Welding & Hot Work'!D8>=0.9,"Gold",IF('Welding & Hot Work'!D8>=0.8,"Silver",IF('Welding & Hot Work'!D8>=0.51,"Bronze","Developing"))))) -> Developing | F34: =COUNTIF('Welding & Hot Work'!E19:E30,"Low")+COUNTIF('Welding & Hot Work'!E19:E30,"Moderate")+COUNTIF('Welding & Hot Work'!E19:E30,"High")+COUNTIF('Welding & Hot Work'!E19:E30,"Very High") -> 0
A35: BBP & Sanitation | B35: ='BBP & Sanitation'!B8 -> 0 | C35: ='BBP & Sanitation'!C8 -> 96 | D35: ='BBP & Sanitation'!D8 -> 0 | E35: =IF('BBP & Sanitation'!D8="N/A","N/A",IF('BBP & Sanitation'!D8>=0.99,"Excellence Leader",IF('BBP & Sanitation'!D8>=0.9,"Gold",IF('BBP & Sanitation'!D8>=0.8,"Silver",IF('BBP & Sanitation'!D8>=0.51,"Bronze","Developing"))))) -> Developing | F35: =COUNTIF('BBP & Sanitation'!E19:E35,"Low")+COUNTIF('BBP & Sanitation'!E19:E35,"Moderate")+COUNTIF('BBP & Sanitation'!E19:E35,"High")+COUNTIF('BBP & Sanitation'!E19:E35,"Very High") -> 0
A37: DETAILED FINDINGS — All items rated Low or above, sorted by severity
A38: ⚠ Items marked with SIF = Serious Injury or Fatality potential. These should be prioritized for immediate corrective action regardless of overall score.
A39: Section | B39: Item # | C39: SIF | D39: Requirement (Summary) | E39: Observations | F39: Recommendations | G39: Citation
A40: No reportable findings — all items Verified or Not Applicable

Sheet CA Tracker
A1: WLS AUDIT COACH OSHA — CORRECTIVE ACTION TRACKER
A2: Auto-populated from audit findings | Prepared under attorney-client privilege | Findings sorted: Very High → Low
A3: ⚑ Columns A–G are auto-populated from audit results and will update as findings are entered. Enter tracking data in columns H–L. Use Item # (col B) as the key if re-alignment is needed between audits.
A5: Section / Tab | B5: Item # | C5: Finding Rating | D5: Requirement | E5: Observations | F5: Recommendations | G5: Citation | H5: Auditor Notes | I5: Assigned To | J5: Due Date | K5: Status | L5: Verified By | M5: Close Date
A6: No findings requiring corrective action

Sheet Confined Space
A1: CONFINED SPACE (PRCS) COMPLIANCE AUDIT | M1: Rating | N1: Pct
A2: 29 CFR 1910.146 — Permit-Required Confined Spaces. Prepared under attorney-client privilege. | M2: Best Practice | N2: 100
M3: Verified | N3: 100
A4: SITE: | B4: ='Pre-Audit Scoping'!D5 -> Test | D4: DATE(S): | E4: ='Pre-Audit Scoping'!D10 -> July 7-9 2026 | G4: AUDITOR(S): | H4: =TRIM('Pre-Audit Scoping'!D11)&IF(TRIM('Pre-Audit Scoping'!D12)<>"",", "&TRIM('Pre-Audit Scoping'!D12),"") -> Sara Wallon, Gabriel Wallon | M4: Low | N4: 85
M5: Moderate | N5: 70
A6: SCORING SUMMARY | M6: High | N6: 30
A7: Category | B7: Score | C7: Max | D7: Percentage % | F7: Finding Rating | G7: Count | M7: Very High | N7: 0
A8: TOTAL | B8: =SUM(F18:F48) -> 98.6 | C8: =SUM(O18:O48) -> 160 | D8: =IF(C8<>0,B8/C8,"N/A") -> 0.61625 | F8: Best Practice | G8: =COUNTIF(E18:E48,"Best Practice") -> 3 | M8: Not Applicable | N8: 0
F9: Verified | G9: =COUNTIF(E18:E48,"Verified") -> 3
F10: Low | G10: =COUNTIF(E18:E48,"Low") -> 4
F11: Moderate | G11: =COUNTIF(E18:E48,"Moderate") -> 3
F12: High | G12: =COUNTIF(E18:E48,"High") -> 3
F13: Very High | G13: =COUNTIF(E18:E48,"Very High") -> 4
F14: Not Applicable | G14: =COUNTIF(E18:E48,"Not Applicable") -> 4
A15: OVERALL SCORE | D15: =D8 -> 0.61625 | F15: Rating Tier: | G15: =IF(D8="N/A","N/A",IF(D8>=0.99,"Excellence Leader",IF(D8>=0.9,"Gold",IF(D8>=0.8,"Silver",IF(D8>=0.51,"Bronze","Developing"))))) -> Bronze
A17: Item # | B17: Subsection | C17: Requirement | D17: Evidence to Look For | E17: Finding Rating | F17: Score | G17: Max | H17: Observations | I17: Recommendations | J17: Citation | K17: Auditor Notes | O17: Eff. Max
A18: GENERAL REQUIREMENTS
A19: CS-1 | B19: General Requirements | C19: The employer must evaluate the workplace to determine if any spaces qualify as permit-required confined spaces (PRCS). A permit-required confined space is a space that: (1) is large enough and configured so an employee can bodily enter and perform assigned work; (2) has limited or restricted means for entry or exit; AND (3) is not designed for continuous employee occupancy; AND meets one or more of: contains or has the potential to contain a serious atmospheric hazard; contains a material with potential for engulfment; has an internal configuration that could trap or asphyxiate an entrant; contains any other recognized serious safety or health hazard. | D19: Request the written confined space inventory/survey document. Walk 10% of the facility (minimum 3 representative areas — processing areas, utility rooms, below-grade areas, material handling areas) and confirm the inventory captures all spaces meeting the PRCS definition. Look for commonly missed spaces: dust collector hoppers, conveyor pits, below-grade sumps, enclosed ductwork, storage bins, silos, and large tanks. Confirm the inventory is signed, dated, and updated when the facility layout changes. | E19: Not Applicable | F19: =IFERROR(ROUND(G19*VLOOKUP(E19,$M$2:$N$8,2,FALSE())/100,1),0) -> 0 | G19: 10 | H19: Test | I19: Test Method 123 | J19: 29 CFR 1910.146(c)(1),(c)(6) | O19: =IF(E19="Not Applicable",0,G19) -> 0
A20: CS-2 | B20: General Requirements | C20: Each identified permit-required confined space must be identified by posting a warning sign at or near the entry point. Signs must include wording such as: 'DANGER — PERMIT-REQUIRED CONFINED SPACE — AUTHORIZED ENTRANTS ONLY' (or equivalent language that conveys the hazard). If signage is not practical, another equally effective means of informing employees must be used. | D20: Walk to 100% of identified PRCS locations and confirm warning signs are posted at or near each entry point. Signs must be visible before an employee could inadvertently enter the space. Document any identified PRCS that lacks a sign or where the sign is obscured, illegible, or outdated. | E20: Low | F20: =IFERROR(ROUND(G20*VLOOKUP(E20,$M$2:$N$8,2,FALSE())/100,1),0) -> 6.8 | G20: 8 | H20: Testing is cool | I20: testing is the best | J20: 29 CFR 1910.146(c)(2) | O20: =IF(E20="Not Applicable",0,G20) -> 8
A21: CS-3 | B21: General Requirements | C21: If the employer decides employees will not enter any confined space, the employer must take effective measures to prevent employee entry — not just post a sign. Effective measures include: welding or bolting covers shut, installing padlocked barriers, or other physical means that prevent unauthorized access. | D21: Confirm whether any spaces on the inventory are designated no-entry. If yes, physically inspect 100% of no-entry spaces and confirm physical prevention measures are in place (not just a sign or verbal instruction). Verify employees and contractors know the no-entry designation and understand they may not enter under any circumstances without a program revision. | E21: Very High | F21: =IFERROR(ROUND(G21*VLOOKUP(E21,$M$2:$N$8,2,FALSE())/100,1),0) -> 0 | G21: 6 | H21: trial and tribulation | I21: test | J21: 29 CFR 1910.146(c)(3) | O21: =IF(E21="Not Applicable",0,G21) -> 6
A22: CONTRACTORS
A23: CS-4 | B23: Contractors | C23: When contractors perform work at this facility, the host employer must: (1) Inform the contractor that the workplace contains permit-required confined spaces. (2) Inform the contractor of the spaces' locations and the hazards present. (3) Inform the contractor of the employer's experience with the spaces. (4) Inform the contractor of any precautions or procedures implemented for protection. (5) Coordinate entry operations if both employer and contractor will be working in or near a PRCS simultaneously. (6) Debrief the contractor after entry operations to identify any hazards discovered. | D23: Request documentation of contractor coordination for 10% of contractor jobs involving PRCS work at this facility in the past year (minimum 1 job). Confirm: the host shared the space inventory and known hazards before work began; there is a record of the pre-entry information exchange (sign-in sheet, pre-job meeting notes, or contractor safety form); and if both host and contractor worked in or near the same space simultaneously, a coordination protocol is documented. | E23: Not Applicable | F23: =IFERROR(ROUND(G23*VLOOKUP(E23,$M$2:$N$8,2,FALSE())/100,1),0) -> 0 | G23: 8 | J23: 29 CFR 1910.146(c)(8),(c)(9) | O23: =IF(E23="Not Applicable",0,G23) -> 0
A24: PERMIT-REQUIRED CONFINED SPACE PROGRAM
A25: CS-5 | B25: Permit-Required Confined Space Program | C25: An employer whose employees enter permit spaces must develop and implement a written PRCS entry program. The program must be made available for inspection by employees and their authorized representatives. | D25: Request the written PRCS program. Confirm: (1) it is site-specific, not a generic template; (2) it references the specific spaces at this facility; (3) it includes a current revision date; (4) it is physically accessible to employees and authorized employee representatives — not solely in a manager's office or a locked file. A printed copy posted near the entry or maintained in the work area meets this requirement. | E25: Low | F25: =IFERROR(ROUND(G25*VLOOKUP(E25,$M$2:$N$8,2,FALSE())/100,1),0) -> 8.5 | G25: 10 | J25: 29 CFR 1910.146(c)(4),(d)(1)-(d)(2),(l) | O25: =IF(E25="Not Applicable",0,G25) -> 10
A26: CS-6 | B26: Permit-Required Confined Space Program | C26: The written PRCS program must include ALL 14 required elements per 29 CFR 1910.146(d)(3)-(d)(14). Missing any element is a citable deficiency. See the Evidence column checklist. | D26: CHECKLIST — review the written PRCS program against each element. Mark each: Verified (complete), Partial (exists but incomplete), or Absent (not addressed at all). □ (1) Measures to prevent unauthorized entry □ (2) Identification and evaluation of hazards before entry □ (3) Safe entry procedures: acceptable entry conditions; isolation from energy/material sources; condition verification throughout entry; purging/inerting/flushing/ventilation to control atmospheric hazards; pedestrian/vehicle barriers □ (4) Equipment at no cost: testing instruments, ventilation, communications, PPE, lighting, ingress/egress, rescue gear □ (5) Atmospheric testing and monitoring before and during entry □ (6) At least one dedicated attendant stationed outside for the full duration of every authorized entry □ (7) Multi-space attendant protocol if one attendant monitors simultaneous entries □ (8) Designated roles with responsibilities: authorized entrants, attendants, entry supervisors, rescuers □ (9) Rescue and emergency services — on-site trained team or identified external service □ (10) Permit system: preparation, issuance, use, and cancellation □ (11) Multi-employer coordination when >1 employer works in or near the space simultaneously □ (12) Entry conclusion and permit cancellation procedures □ (13) Pre-entry hazard re-evaluation when conditions may have changed □ (14) Annual program review using canceled permits as input Elements (6), (9), and (14) are most frequently missing — verify these first. | E26: High | F26: =IFERROR(ROUND(G26*VLOOKUP(E26,$M$2:$N$8,2,FALSE())/100,1),0) -> 3 | G26: 10 | J26: 29 CFR 1910.146(d)(3),(d)(6)-(d)(14) | O26: =IF(E26="Not Applicable",0,G26) -> 10
A27: CS-7 | B27: Permit-Required Confined Space Program | C27: The employer must provide and maintain all equipment necessary for safe PRCS entry at no cost to the employee. Required equipment includes: (1) Testing and monitoring equipment for atmospheric hazards (calibrated multi-gas meter for O2, LEL, CO, and H2S at minimum); (2) Ventilating equipment sufficient to obtain acceptable entry conditions; (3) Communications equipment; (4) Personal protective equipment; (5) Lighting equipment to enable employees to see well enough to work safely and exit quickly in an emergency; (6) Barriers and shields; (7) Equipment for safe ingress and egress; (8) Rescue and emergency equipment. | D27: Physically inspect the confined space entry equipment station. Verify: (1) Multi-gas meter is present, powered on, and the calibration date on the tag or in the log is current (most meters require bump testing before each use and full calibration per manufacturer schedule — typically every 6 months); (2) Ventilation blower is present and functional; (3) Communications device (radio or phone) is present and working; (4) Rescue retrieval equipment (tripod, winch, or davit) is present and in serviceable condition; (5) Full-body harness and retrieval lifeline are present; (6) Lighting is available. Sample 10% of confined space entry equipment kits at this facility (minimum 1 full kit inspection). | E27: Moderate | F27: =IFERROR(ROUND(G27*VLOOKUP(E27,$M$2:$N$8,2,FALSE())/100,1),0) -> 7 | G27: 10 | J27: 29 CFR 1910.146(d)(4) | O27: =IF(E27="Not Applicable",0,G27) -> 10
A28: CS-8 | B28: Permit-Required Confined Space Program | C28: Atmospheric monitoring must be conducted: (1) Before entry authorization is granted — to test for the presence of atmospheric hazards. (2) As needed during entry — to ensure acceptable entry conditions are maintained for the duration of the entry. Testing must be conducted by or under the direction of a qualified person using properly calibrated instruments. The atmosphere must be tested for: oxygen content (acceptable range: 19.5% to 23.5%); flammable gases and vapors (must be less than 10% of LFL); potential toxic air contaminants (below applicable PEL). | D28: Pull 10% of canceled entry permits from the past 12 months (minimum 5 permits). For each permit: confirm pre-entry atmospheric test results are recorded with the actual readings (not just a checkmark), the name of the person who performed the test, and the instrument used. Confirm readings were within acceptable ranges before entry was authorized. Confirm that any permit where continuous monitoring was required shows monitoring notes during the entry. Any permit with blank atmospheric test fields is a deficiency. | E28: Very High | F28: =IFERROR(ROUND(G28*VLOOKUP(E28,$M$2:$N$8,2,FALSE())/100,1),0) -> 0 | G28: 10 | J28: 29 CFR 1910.146(d)(5) | O28: =IF(E28="Not Applicable",0,G28) -> 10
A29: CS-9 | B29: Permit-Required Confined Space Program | C29: An employer may use an alternate procedure (continuous forced-air ventilation without a full permit) ONLY when ALL of the following conditions are met: (1) The only hazard in the space is an actual or potential hazardous atmosphere; (2) The hazardous atmosphere can be controlled by continuous forced-air ventilation alone; (3) The employer can demonstrate that entry can be made safely; (4) The written program describes the means, procedures, and practices used; (5) The atmosphere is tested before any employee enters to confirm the ventilation has worked; (6) Atmospheric testing continues as necessary. | D29: For any spaces designated as alternate-entry (non-permit entry with ventilation), confirm the written program documents specifically that: (1) the space has been evaluated and the ONLY hazard is atmospheric; (2) ventilation controls the hazard; (3) pre-entry and continuous atmospheric monitoring is performed. Walk 10% of alternate-entry spaces (minimum 1) and confirm ventilation equipment is in place and functional. Any space with an engulfment hazard, converging walls, or uncontrolled energy cannot qualify for alternate entry. | E29: Best Practice | F29: =IFERROR(ROUND(G29*VLOOKUP(E29,$M$2:$N$8,2,FALSE())/100,1),0) -> 6 | G29: 6 | J29: 29 CFR 1910.146(c)(5) | O29: =IF(E29="Not Applicable",0,G29) -> 6
A30: CS-10 | B30: Permit-Required Confined Space Program | C30: When an alternate entry procedure is used, the employer must: (1) Test the atmosphere within the space before any employee enters to demonstrate the ventilation has worked. (2) Continue atmospheric testing as often as necessary to ensure acceptable conditions exist throughout the entry. (3) If a hazardous atmosphere is detected during entry, have each employee leave the space immediately and investigate, evaluate, and remedy the hazardous atmosphere before re-entering. | D30: Review 10% of alternate-entry records (minimum 2). Confirm: pre-entry atmospheric readings are recorded with the actual values; continuous monitoring requirements are documented; and there is a documented procedure (or training record showing employees know) to evacuate immediately if conditions change. | E30: Verified | F30: =IFERROR(ROUND(G30*VLOOKUP(E30,$M$2:$N$8,2,FALSE())/100,1),0) -> 6 | G30: 6 | J30: 29 CFR 1910.146(c)(5)(ii) | O30: =IF(E30="Not Applicable",0,G30) -> 6
